<?xml version="1.0"?>
<robot name="assem6">

  <!-- ros2_control hardware interface -->
  <ros2_control name="GazeboSystem" type="system">
    <hardware>
      <plugin>gazebo_ros2_control/GazeboSystem</plugin>
    </hardware>
    <joint name="joint1">
      <command_interface name="position">
        <param name="min">-3.14</param>
        <param name="max">3.14</param>
      </command_interface>
      <state_interface name="position"/>
      <state_interface name="velocity"/>
    </joint>
    <joint name="joint2">
      <command_interface name="position">
        <param name="min">-1.57</param>
        <param name="max">1.57</param>
      </command_interface>
      <state_interface name="position"/>
      <state_interface name="velocity"/>
    </joint>
    <joint name="joint3">
      <command_interface name="position">
        <param name="min">-1.57</param>
        <param name="max">1.57</param>
      </command_interface>
      <state_interface name="position"/>
      <state_interface name="velocity"/>
    </joint>
    <joint name="joint4">
      <command_interface name="position">
        <param name="min">-3.14</param>
        <param name="max">3.14</param>
      </command_interface>
      <state_interface name="position"/>
      <state_interface name="velocity"/>
    </joint>
  </ros2_control>

  <!-- Gazebo ros2_control plugin -->
  <gazebo>
    <plugin filename="libgazebo_ros2_control.so" name="gazebo_ros2_control">
      <robot_param>robot_description</robot_param>
      <robot_param_node>robot_state_publisher</robot_param_node>
      <parameters>/home/mma/x-bot/install/assem6/share/assem6/config/ros2_controllers.yaml</parameters>
    </plugin>
  </gazebo>

  <!-- Gazebo colors -->
  <gazebo reference="base_link">
    <material>Gazebo/Blue</material>
  </gazebo>
  <gazebo reference="link1">
    <material>Gazebo/Orange</material>
  </gazebo>
  <gazebo reference="link2">
    <material>Gazebo/Green</material>
  </gazebo>
  <gazebo reference="link3">
    <material>Gazebo/Red</material>
  </gazebo>
  <gazebo reference="link4">
    <material>Gazebo/Yellow</material>
  </gazebo>

  <!-- World link -->
  <link name="world"/>
  
  <joint name="world_fixed" type="fixed">
    <parent link="world"/>
    <child link="base_link"/>
    <origin xyz="0 0 0.5" rpy="0 0 0"/>
  </joint>

  <link name="base_link">
    <inertial>
      <origin xyz="0.036 0.040 -0.070" rpy="0 0 0"/>
      <mass value="5.0"/>
      <inertia ixx="0.1" ixy="0" ixz="0" iyy="0.1" iyz="0" izz="0.1"/>
    </inertial>
    <visual>
      <origin xyz="0 0 0" rpy="0 0 0"/>
      <geometry>
        <mesh filename="package://assem6/meshes/base_link.STL"/>
      </geometry>
      <material name="blue">
        <color rgba="0 0 0.8 1"/>
      </material>
    </visual>
    <collision>
      <origin xyz="0 0 0" rpy="0 0 0"/>
      <geometry>
        <mesh filename="package://assem6/meshes/base_link.STL"/>
      </geometry>
    </collision>
  </link>

  <link name="link1">
    <inertial>
      <origin xyz="0 -0.013 0.097" rpy="0 0 0"/>
      <mass value="0.5"/>
      <inertia ixx="0.002" ixy="0" ixz="0" iyy="0.002" iyz="0" izz="0.002"/>
    </inertial>
    <visual>
      <origin xyz="0 0 0" rpy="0 0 0"/>
      <geometry>
        <mesh filename="package://assem6/meshes/link1.STL"/>
      </geometry>
      <material name="orange">
        <color rgba="1 0.5 0 1"/>
      </material>
    </visual>
    <collision>
      <origin xyz="0 0 0" rpy="0 0 0"/>
      <geometry>
        <mesh filename="package://assem6/meshes/link1.STL"/>
      </geometry>
    </collision>
  </link>

  <joint name="joint1" type="revolute">
    <origin xyz="0.033986 -0.081844 0.011835" rpy="0 0 0"/>
    <parent link="base_link"/>
    <child link="link1"/>
    <axis xyz="0 0 1"/>
    <limit lower="-3.14" upper="3.14" effort="100" velocity="1.0"/>
    <dynamics damping="0.5" friction="0.1"/>
  </joint>

  <link name="link2">
    <inertial>
      <origin xyz="0 0.2 0.1" rpy="0 0 0"/>
      <mass value="1.0"/>
      <inertia ixx="0.01" ixy="0" ixz="0" iyy="0.005" iyz="0" izz="0.01"/>
    </inertial>
    <visual>
      <origin xyz="0 0 0" rpy="0 0 0"/>
      <geometry>
        <mesh filename="package://assem6/meshes/link2.STL"/>
      </geometry>
      <material name="green">
        <color rgba="0 0.8 0 1"/>
      </material>
    </visual>
    <collision>
      <origin xyz="0 0 0" rpy="0 0 0"/>
      <geometry>
        <mesh filename="package://assem6/meshes/link2.STL"/>
      </geometry>
    </collision>
  </link>

  <joint name="joint2" type="revolute">
    <origin xyz="0 -0.0625 0.09129" rpy="1.5707963267949 0 0"/>
    <parent link="link1"/>
    <child link="link2"/>
    <axis xyz="0 0 1"/>
    <limit lower="-1.57" upper="1.57" effort="100" velocity="1.0"/>
    <dynamics damping="0.5" friction="0.1"/>
  </joint>

  <link name="link3">
    <inertial>
      <origin xyz="0 0.19 0.07" rpy="0 0 0"/>
      <mass value="1.0"/>
      <inertia ixx="0.01" ixy="0" ixz="0" iyy="0.005" iyz="0" izz="0.01"/>
    </inertial>
    <visual>
      <origin xyz="0 0 0" rpy="0 0 0"/>
      <geometry>
        <mesh filename="package://assem6/meshes/link3.STL"/>
      </geometry>
      <material name="red">
        <color rgba="0.8 0 0 1"/>
      </material>
    </visual>
    <collision>
      <origin xyz="0 0 0" rpy="0 0 0"/>
      <geometry>
        <mesh filename="package://assem6/meshes/link3.STL"/>
      </geometry>
    </collision>
  </link>

  <joint name="joint3" type="revolute">
    <origin xyz="0 0.378542203070813 0.0288" rpy="-3.14159265358979 0 3.14159265358979"/>
    <parent link="link2"/>
    <child link="link3"/>
    <axis xyz="0 0 1"/>
    <limit lower="-1.57" upper="1.57" effort="100" velocity="1.0"/>
    <dynamics damping="0.5" friction="0.1"/>
  </joint>

  <link name="link4">
    <inertial>
      <origin xyz="0 0.047 -0.04" rpy="0 0 0"/>
      <mass value="0.3"/>
      <inertia ixx="0.0005" ixy="0" ixz="0" iyy="0.0003" iyz="0" izz="0.0004"/>
    </inertial>
    <visual>
      <origin xyz="0 0 0" rpy="0 0 0"/>
      <geometry>
        <mesh filename="package://assem6/meshes/link4.STL"/>
      </geometry>
      <material name="yellow">
        <color rgba="1 1 0 1"/>
      </material>
    </visual>
    <collision>
      <origin xyz="0 0 0" rpy="0 0 0"/>
      <geometry>
        <mesh filename="package://assem6/meshes/link4.STL"/>
      </geometry>
    </collision>
  </link>

  <joint name="joint4" type="revolute">
    <origin xyz="0 0.39129 0.1158" rpy="0 0 0"/>
    <parent link="link3"/>
    <child link="link4"/>
    <axis xyz="0 0 1"/>
    <limit lower="-3.14" upper="3.14" effort="100" velocity="1.0"/>
    <dynamics damping="0.5" friction="0.1"/>
  </joint>

</robot>
